Workbook

Sheet reference_stuff
A1: Aegis' Speedrunner's Shopping List (updated 2026-01-05)
A2: =HYPERLINK("https://drive.google.com/drive/folders/1-bY43R_FDEsUXsidDFVB3F7rIHlW3VMM") -> https://drive.google.com/drive/folders/1-bY43R_FDEsUXsidDFVB3F7rIHlW3VMM | B2: <- Speedrunning Folder
A3: https://docs.google.com/spreadsheets/d/1is4sNUesy--7Zm6SCCWEP9PAXomxaSj5xlJGCsSj_qs | B3: <- Speedrunner Spreadsheet
A4: =HYPERLINK("https://raw.githubusercontent.com/JxPv2/Destiny2/main/dim_wishlists/aegis'%20speedrunner's%20shopping%20list") -> https://raw.githubusercontent.com/JxPv2/Destiny2/main/dim_wishlists/aegis'%20speedrunner's%20shopping%20list | B4: <- Raw Wishlist

Sheet import_speedrun
A1: # | B1: Pic | C1: Name | D1: Rarity | E1: Slot | F1: Affinity | G1: Type | H1: Ammo | I1: Column 1 | J1: Column 2 | K1: Perk 1 | L1: Perk 2 | M1: Purpose | N1: Usage | O1: Source
A2: 1 | B2: #VALUE! | C2: Ergo Sum | D2: Exotic | E2: Energy | F2: #VALUE! | G2: #VALUE! | H2: #VALUE! | I2: Enduring Blade | J2: Swordmaster's Guard | K2: Caster Frame Lightweight Frame Wave Frame | L2: Arc Conductor The Perfect Fifth Wolfpack Rounds | M2: Splash add clear Sword boss damage | N2: CE, SE | O2: Pale Heart
A3: 1 | B3: #VALUE! | C3: Gizmo Weft | D3: Legendary | E3: Kinetic | F3: #VALUE! | G3: #VALUE! | H3: #VALUE! | I3: Quick Launch | J3: High-Velocity Rounds Spike Grenades Sticky Grenades | K3: Air Trigger Slideshot | L3: Bipod | M3: Boosting jump height | N3: Universal | O3: Event drop
A4: 1 | B4: #VALUE! | C4: Mint Retrograde | D4: Legendary | E4: Kinetic | F4: #VALUE! | G4: #VALUE! | H4: #VALUE! | I4: Quick Launch | J4: High-Velocity Rounds High-Explosive Ordnance | K4: Rewind Rounds Hatchling Beacon Rounds | L4: Elemental Honing Bait and Switch Chain Reaction Master of Arms | M4: Everything | N4: Universal | O4: Hawthorne
A5: 1 | B5: #VALUE! | C5: Praxic Blade | D5: Exotic | E5: Kinetic | F5: #VALUE! | G5: #VALUE! | H5: #VALUE! | I5: Offensive Form | J5: Blade Ammo | K5: Impact Core | L5: Hyperblade | M5: Hyperlining | N5: Universal | O5: Renegades quest
A6: 1 | B6: #VALUE! | C6: Psi Aeterna IV | D6: Legendary | E6: Energy | F6: #VALUE! | G6: #VALUE! | H6: #VALUE! | I6: Quick Launch | J6: High-Velocity Rounds High-Explosive Ordnance | K6: Blast Distributor Trickle Charge Beacon Rounds | L6: Elemental Honing Rolling Storm One for All | M6: Everything | N6: Universal | O6: S28 portal
A7: 1 | B7: #VALUE! | C7: Sullen Claw | D7: Legendary | E7: Power | F7: #VALUE! | G7: #VALUE! | H7: #VALUE! | I7: Tempered Edge | J7: Heavy Guard | K7: Eager Edge Vorpal Weapon | L7: Assassin's Blade Whirlwind Blade | M7: Movement | N7: Universal | O7: Equilibrium
A8: 1 | B8: #VALUE! | C8: The Navigator | D8: Exotic | E8: Kinetic | F8: #VALUE! | G8: #VALUE! | H8: #VALUE! | I8: Fixed | J8: Fixed | K8: Fixed | L8: Fixed | M8: Creating grapple points | N8: Universal | O8: Ghosts of the Deep
A9: 1 | B9: #VALUE! | C9: The Slammer | D9: Legendary | E9: Power | F9: #VALUE! | G9: #VALUE! | H9: #VALUE! | I9: Tempered Edge | J9: Heavy Guard Enduring Guard | K9: Eager Edge | L9: Cold Steel Demolitionist | M9: Movement Overload stunning | N9: Universal | O9: Nightfalls
A10: 1 | B10: #VALUE! | C10: Theodolite | D10: Legendary | E10: Energy | F10: #VALUE! | G10: #VALUE! | H10: #VALUE! | I10: Quick Launch | J10: High-Velocity Rounds Spike Grenades Sticky Grenades | K10: Reconstruction | L10: Frenzy | M10: Boosting jump height | N10: Universal | O10: Hawthorne
A11: 1 | B11: #VALUE! | C11: Tractor Cannon | D11: Exotic | E11: Power | F11: #VALUE! | G11: #VALUE! | H11: #VALUE! | I11: Fixed | J11: Fixed | K11: Fixed | L11: Fixed | M11: Swappable 10s 30% debuff Enemy displacement | N11: Universal | O11: New Light quest
A12: 1 | B12: #VALUE! | C12: Uncivil Discourse | D12: Legendary | E12: Energy | F12: #VALUE! | G12: #VALUE! | H12: #VALUE! | I12: Fluted Barrel | J12: Ionized Heatsink | K12: Air Trigger | L12: Precision Instrument | M12: Lucky Pants burst damage | N12: Universal | O12: Lawless Frontier
A13: 2 | B13: #VALUE! | C13: A Good Shout | D13: Legendary | E13: Power | F13: #VALUE! | G13: #VALUE! | H13: #VALUE! | I13: Ultralight Rail | J13: Charged Bolts Serrated Bolts Heavy Bolts | K13: Envious Arsenal | L13: High Ground | M13: Sustained boss damage | N13: Universal | O13: S28 portal
... A52: 3 | B52: #VALUE! | C52: Critical Anomaly | D52: Legendary | E52: Kinetic | F52: #VALUE! | G52: #VALUE! | H52: #VALUE! | I52: Fluted Barrel | J52: Tactical Mag | K52: Chill Clip Rewind Rounds | L52: Chaos Reshaped | M52: Artifact-independent Overload | N52: Universal | O52: Salvation's Edge
A53: 3 | B53: #VALUE! | C53: Cusp Sempiternal | D53: Legendary | E53: Energy | F53: #VALUE! | G53: #VALUE! | H53: #VALUE! | I53: Fluted Barrel | J53: Accurized Rounds | K53: Impulse Amplifier Repulsor Brace Reciprocity | L53: Destabilizing Rounds Circle of Life | M53: Healing vulnerable teammates Universal damage boost | N53: Universal
A54: 3 | B54: #VALUE! | C54: Divinity | D54: Exotic | E54: Energy | F54: #VALUE! | G54: #VALUE! | H54: #VALUE! | I54: Fixed | J54: Fixed | K54: Fixed | L54: Fixed | M54: 15% debuff with crit bubble Intrinsic overload | N54: GMs | O54: Garden of Salvation
A55: 3 | B55: #VALUE! | C55: Edge Transit BRAVE version | D55: Legendary | E55: Power | F55: #VALUE! | G55: #VALUE! | H55: #VALUE! | I55: Quick Launch | J55: Sticky Grenades | K55: Cascade Point | L55: Explosive Light | M55: Burst boss damage | N55: Universal | O55: Onslaught
A56: 3 | B56: #VALUE! | C56: Eriana's Vow | D56: Exotic | E56: Energy | F56: #VALUE! | G56: #VALUE! | H56: #VALUE! | I56: Fixed | J56: Fixed | K56: Fixed | L56: Fixed | M56: Rapid piercing damage Destroying oracles Death Throes stacking Long range hitscan Barrier | N56: VoG, Duality, VotD | O56: Monument to Lost Lights
A57: 3 | B57: #VALUE! | C57: Ex Diris | D57: Exotic | E57: Energy | F57: #VALUE! | G57: #VALUE! | H57: #VALUE! | I57: Fixed | J57: Fixed | K57: Fixed | L57: Fixed | M57: Dying quickly | N57: Universal | O57: Monument to Lost Lights
A58: 3 | B58: #VALUE! | C58: Finality's Auger | D58: Exotic | E58: Power | F58: #VALUE! | G58: #VALUE! | H58: #VALUE! | I58: Fixed | J58: Fixed | K58: Fixed | L58: Fixed | M58: Trapping doors | N58: VoG | O58: Sundered Doctrine
A59: 3 | B59: #VALUE! | C59: Ice Breaker | D59: Exotic | E59: Energy | F59: #VALUE! | G59: #VALUE! | H59: #VALUE! | I59: Fixed | J59: Fixed | K59: Fixed | L59: Fixed | M59: Ammo generation | N59: Universal | O59: Vesper's Host
A60: 3 | B60: #VALUE! | C60: Imperial Decree | D60: Legendary | E60: Kinetic | F60: #VALUE! | G60: #VALUE! | H60: #VALUE! | I60: Barrel Shroud | J60: Assault Mag | K60: Auto-Loading Holster | L60: Trench Barrel Surrounded | M60: Burst single target damage Slow single weapon damage | N60: Universal | O60: S20 focusing
A61: 3 | B61: #VALUE! | C61: Martyr's Retribution | D61: Legendary | E61: Energy | F61: #VALUE! | G61: #VALUE! | H61: #VALUE! | I61: Quick Launch | J61: High-Velocity Rounds | K61: Heal Clip Demolitionist Auto-Loading Holster | L61: Incandescent Kill Clip | M61: Ammo efficient add clear | N61: Universal | O61: S24 pool
A62: 3 | B62: #VALUE! | C62: New Malpais | D62: Exotic | E62: Kinetic | F62: #VALUE! | G62: #VALUE! | H62: #VALUE! | I62: Fixed | J62: Fixed | K62: Fixed | L62: Fixed | M62: Trapping spawns Pre-activating objectives | N62: TST, SotW | O62: Monument to Lost Lights
A63: 3 | B63: #VALUE! | C63: Praedyth's Revenge | D63: Legendary | E63: Kinetic | F63: #VALUE! | G63: #VALUE! | H63: #VALUE! | I63: Fluted Barrel | J63: Tactical Mag | K63: Kinetic Tremors Fourth Time's the Charm | L63: Elemental Honing Bait and Switch | M63: Quick ranged hitscan kills Augmenting boss damage | N63: Universal | O63: Vault of Glass
A64: 3 | B64: #VALUE! | C64: Tarnation | D64: Legendary | E64: Power | F64: #VALUE! | G64: #VALUE! | H64: #VALUE! | I64: Volatile Launch | J64: High-Explosive Ordnance | K64: Field Prep | L64: Danger Zone | M64: Vault add clear | N64: Last Wish | O64: Throne World pool
A65: 3 | B65: #VALUE! | C65: The Call | D65: Legendary | E65: Kinetic | F65: #VALUE! | G65: #VALUE! | H65: #VALUE! | I65: Volatile Launch | J65: High-Explosive Ordnance | K65: Slice Lead from Gold Demolitionist | L65: Desperate Measures Golden Tricorn One for All | M65: Avoiding primary swaps Ammo efficient fast add clear | N65: Universal | O65: Pale Heart pool
... A77: 3 | B77: #VALUE! | C77: Xenophage | D77: Exotic | E77: Power | F77: #VALUE! | G77: #VALUE! | H77: #VALUE! | I77: Fixed | J77: Fixed | K77: Fixed | L77: Fixed | M77: Ranged hitscan bursts | N77: Universal | O77: Pit of Heresy
A78: N/A | B78: #VALUE! | C78: Acasia's Dejection | D78: Legendary | E78: Energy | F78: #VALUE! | G78: #VALUE! | H78: #VALUE! | I78: Fluted Barrel | J78: Light Battery | K78: Reconstruction Field Prep | L78: Frenzy Paracausal Affinity | M78: Avoiding primary swaps Special single shot add clear | N78: Universal | O78: Root of Nightmares
A79: N/A | B79: #VALUE! | C79: Apex Predator | D79: Legendary | E79: Power | F79: #VALUE! | G79: #VALUE! | H79: #VALUE! | I79: Quick Launch | J79: Impact Casing | K79: Reconstruction | L79: Bait and Switch Bipod Surrounded | M79: Burst splash damage | N79: Universal | O79: Last Wish
A80: N/A | B80: #VALUE! | C80: Arbalest | D80: Exotic | E80: Kinetic | F80: #VALUE! | G80: #VALUE! | H80: #VALUE! | I80: Fixed | J80: Fixed | K80: Fixed | L80: Fixed | M80: Single target piercing damage Intrinsic Barrier | N80: GMs | O80: Intro exotic quest
A81: N/A | B81: #VALUE! | C81: Arcane Embrace | D81: Legendary | E81: Energy | F81: #VALUE! | G81: #VALUE! | H81: #VALUE! | I81: Fluted Barrel | J81: Assault Mag | K81: Fourth Time's the Charm Air Trigger Grave Robber | L81: Precision Instrument Surrounded | M81: Fastest Cascade trigger | N81: Universal | O81: Festival of the Lost
A82: N/A | B82: #VALUE! | C82: Bastion | D82: Exotic | E82: Kinetic | F82: #VALUE! | G82: #VALUE! | H82: #VALUE! | I82: Fixed | J82: Fixed | K82: Fixed | L82: Fixed | M82: Object destruction Intrinsic Unstoppable Ranged long duration 12P | N82: DSC, Prophecy, Lake of Shadows, etc. | O82: Monument to Lost Lights
A83: N/A | B83: #VALUE! | C83: Bitter/Sweet | D83: Legendary | E83: Power | F83: #VALUE! | G83: #VALUE! | H83: #VALUE! | I83: Quick Launch | J83: Spike Grenades Mini Frags | K83: Envious Arsenal | L83: Bait and Switch | M83: Non-rocket burst damage | N83: Universal | O83: S25 pool
A84: N/A | B84: #VALUE! | C84: Briar's Contempt | D84: Legendary | E84: Power | F84: #VALUE! | G84: #VALUE! | H84: #VALUE! | I84: Fluted Barrel | J84: Accelerated Coils | K84: Rewind Rounds | L84: Surrounded | M84: Specialized sustained damage | N84: Universal | O84: Root of Nightmares
A85: N/A | B85: #VALUE! | C85: Bump in the Night | D85: Legendary | E85: Power | F85: #VALUE! | G85: #VALUE! | H85: #VALUE! | I85: Quick Launch | J85: Impact Casing | K85: Demolitionist Auto-Loading Holster | L85: Chill Clip Frenzy | M85: Chill Clip application | N85: SotW | O85: Presage
A86: N/A | B86: #VALUE! | C86: Calus Mini-Tool | D86: Legendary | E86: Energy | F86: #VALUE! | G86: #VALUE! | H86: #VALUE! | I86: Fluted Barrel | J86: Flared Magwell | K86: Threat Detector | L86: Incandescent | M86: General primary | N86: Universal | O86: Presage
A87: N/A | B87: #VALUE! | C87: Cataclysmic | D87: Legendary | E87: Power | F87: #VALUE! | G87: #VALUE! | H87: #VALUE! | I87: Fluted Barrel | J87: Enhanced Battery | K87: Fourth Time's The Charm | L87: Bait and Switch | M87: Ranged sustained damage | N87: Universal | O87: Vow of the Disciple
A88: N/A | B88: #VALUE! | C88: Cataphract GL3 | D88: Legendary | E88: Power | F88: #VALUE! | G88: #VALUE! | H88: #VALUE! | I88: Quick Launch | J88: Spike Grenades | K88: Envious Assassin Auto-Loading Holster | L88: Bait and Switch Cascade Point | M88: Non-rocket burst damage | N88: N/A | O88: Trials of Osiris
A89: N/A | B89: #VALUE! | C89: Cold Comfort | D89: Legendary | E89: Power | F89: #VALUE! | G89: #VALUE! | H89: #VALUE! | I89: Quick Launch | J89: Impact Casing | K89: Envious Assassin | L89: Bait and Switch | M89: Burst splash damage | N89: Universal | O89: Ghosts of the Deep
...

Sheet cleanup_speedrun
A1: Name | B1: Column 1 | C1: Column 2 | D1: Perk 1 | E1: Perk 2 | F1: Tier | G1: Purpose | H1: Usage | I1: Source
A2: Ergo Sum | B2: Enduring Blade | C2: Swordmaster's Guard | D2: Caster Frame Lightweight Frame Wave Frame | E2: Arc Conductor The Perfect Fifth Wolfpack Rounds | F2: 1 | G2: Splash add clear Sword boss damage | H2: CE, SE | I2: Pale Heart
A3: Gizmo Weft | B3: Quick Launch | C3: High-Velocity Rounds Spike Grenades Sticky Grenades | D3: Air Trigger Slideshot | E3: Bipod | F3: 1 | G3: Boosting jump height | H3: Universal | I3: Event drop
A4: Mint Retrograde | B4: Quick Launch | C4: High-Velocity Rounds High-Explosive Ordnance | D4: Rewind Rounds Hatchling Beacon Rounds | E4: Elemental Honing Bait and Switch Chain Reaction Master of Arms | F4: 1 | G4: Everything | H4: Universal | I4: Hawthorne
A5: Praxic Blade | B5: Offensive Form | C5: Blade Ammo | D5: Impact Core | E5: Hyperblade | F5: 1 | G5: Hyperlining | H5: Universal | I5: Renegades quest
A6: Psi Aeterna IV | B6: Quick Launch | C6: High-Velocity Rounds High-Explosive Ordnance | D6: Blast Distributor Trickle Charge Beacon Rounds | E6: Elemental Honing Rolling Storm One for All | F6: 1 | G6: Everything | H6: Universal | I6: S28 portal
A7: Sullen Claw | B7: Tempered Edge | C7: Heavy Guard | D7: Eager Edge Vorpal Weapon | E7: Assassin's Blade Whirlwind Blade | F7: 1 | G7: Movement | H7: Universal | I7: Equilibrium
A8: The Navigator | B8: Fixed | C8: Fixed | D8: Fixed | E8: Fixed | F8: 1 | G8: Creating grapple points | H8: Universal | I8: Ghosts of the Deep
A9: The Slammer | B9: Tempered Edge | C9: Heavy Guard Enduring Guard | D9: Eager Edge | E9: Cold Steel Demolitionist | F9: 1 | G9: Movement Overload stunning | H9: Universal | I9: Nightfalls
A10: Theodolite | B10: Quick Launch | C10: High-Velocity Rounds Spike Grenades Sticky Grenades | D10: Reconstruction | E10: Frenzy | F10: 1 | G10: Boosting jump height | H10: Universal | I10: Hawthorne
A11: Tractor Cannon | B11: Fixed | C11: Fixed | D11: Fixed | E11: Fixed | F11: 1 | G11: Swappable 10s 30% debuff Enemy displacement | H11: Universal | I11: New Light quest
A12: Uncivil Discourse | B12: Fluted Barrel | C12: Ionized Heatsink | D12: Air Trigger | E12: Precision Instrument | F12: 1 | G12: Lucky Pants burst damage | H12: Universal | I12: Lawless Frontier
A13: A Good Shout | B13: Ultralight Rail | C13: Charged Bolts Serrated Bolts Heavy Bolts | D13: Envious Arsenal | E13: High Ground | F13: 2 | G13: Sustained boss damage | H13: Universal | I13: S28 portal
... A52: Critical Anomaly | B52: Fluted Barrel | C52: Tactical Mag | D52: Chill Clip Rewind Rounds | E52: Chaos Reshaped | F52: 3 | G52: Artifact-independent Overload | H52: Universal | I52: Salvation's Edge
A53: Cusp Sempiternal | B53: Fluted Barrel | C53: Accurized Rounds | D53: Impulse Amplifier Repulsor Brace Reciprocity | E53: Destabilizing Rounds Circle of Life | F53: 3 | G53: Healing vulnerable teammates Universal damage boost | H53: Universal
A54: Divinity | B54: Fixed | C54: Fixed | D54: Fixed | E54: Fixed | F54: 3 | G54: 15% debuff with crit bubble Intrinsic overload | H54: GMs | I54: Garden of Salvation
A55: Edge Transit BRAVE version | B55: Quick Launch | C55: Sticky Grenades | D55: Cascade Point | E55: Explosive Light | F55: 3 | G55: Burst boss damage | H55: Universal | I55: Onslaught
A56: Eriana's Vow | B56: Fixed | C56: Fixed | D56: Fixed | E56: Fixed | F56: 3 | G56: Rapid piercing damage Destroying oracles Death Throes stacking Long range hitscan Barrier | H56: VoG, Duality, VotD | I56: Monument to Lost Lights
A57: Ex Diris | B57: Fixed | C57: Fixed | D57: Fixed | E57: Fixed | F57: 3 | G57: Dying quickly | H57: Universal | I57: Monument to Lost Lights
A58: Finality's Auger | B58: Fixed | C58: Fixed | D58: Fixed | E58: Fixed | F58: 3 | G58: Trapping doors | H58: VoG | I58: Sundered Doctrine
A59: Ice Breaker | B59: Fixed | C59: Fixed | D59: Fixed | E59: Fixed | F59: 3 | G59: Ammo generation | H59: Universal | I59: Vesper's Host
A60: Imperial Decree | B60: Barrel Shroud | C60: Assault Mag | D60: Auto-Loading Holster | E60: Trench Barrel Surrounded | F60: 3 | G60: Burst single target damage Slow single weapon damage | H60: Universal | I60: S20 focusing
A61: Martyr's Retribution | B61: Quick Launch | C61: High-Velocity Rounds | D61: Heal Clip Demolitionist Auto-Loading Holster | E61: Incandescent Kill Clip | F61: 3 | G61: Ammo efficient add clear | H61: Universal | I61: S24 pool
A62: New Malpais | B62: Fixed | C62: Fixed | D62: Fixed | E62: Fixed | F62: 3 | G62: Trapping spawns Pre-activating objectives | H62: TST, SotW | I62: Monument to Lost Lights
A63: Praedyth's Revenge | B63: Fluted Barrel | C63: Tactical Mag | D63: Kinetic Tremors Fourth Time's the Charm | E63: Elemental Honing Bait and Switch | F63: 3 | G63: Quick ranged hitscan kills Augmenting boss damage | H63: Universal | I63: Vault of Glass
A64: Tarnation | B64: Volatile Launch | C64: High-Explosive Ordnance | D64: Field Prep | E64: Danger Zone | F64: 3 | G64: Vault add clear | H64: Last Wish | I64: Throne World pool
A65: The Call | B65: Volatile Launch | C65: High-Explosive Ordnance | D65: Slice Lead from Gold Demolitionist | E65: Desperate Measures Golden Tricorn One for All | F65: 3 | G65: Avoiding primary swaps Ammo efficient fast add clear | H65: Universal | I65: Pale Heart pool
... A77: Xenophage | B77: Fixed | C77: Fixed | D77: Fixed | E77: Fixed | F77: 3 | G77: Ranged hitscan bursts | H77: Universal | I77: Pit of Heresy
A78: Acasia's Dejection | B78: Fluted Barrel | C78: Light Battery | D78: Reconstruction Field Prep | E78: Frenzy Paracausal Affinity | F78: N/A | G78: Avoiding primary swaps Special single shot add clear | H78: Universal | I78: Root of Nightmares
A79: Apex Predator | B79: Quick Launch | C79: Impact Casing | D79: Reconstruction | E79: Bait and Switch Bipod Surrounded | F79: N/A | G79: Burst splash damage | H79: Universal | I79: Last Wish
A80: Arbalest | B80: Fixed | C80: Fixed | D80: Fixed | E80: Fixed | F80: N/A | G80: Single target piercing damage Intrinsic Barrier | H80: GMs | I80: Intro exotic quest
A81: Arcane Embrace | B81: Fluted Barrel | C81: Assault Mag | D81: Fourth Time's the Charm Air Trigger Grave Robber | E81: Precision Instrument Surrounded | F81: N/A | G81: Fastest Cascade trigger | H81: Universal | I81: Festival of the Lost
A82: Bastion | B82: Fixed | C82: Fixed | D82: Fixed | E82: Fixed | F82: N/A | G82: Object destruction Intrinsic Unstoppable Ranged long duration 12P | H82: DSC, Prophecy, Lake of Shadows, etc. | I82: Monument to Lost Lights
A83: Bitter/Sweet | B83: Quick Launch | C83: Spike Grenades Mini Frags | D83: Envious Arsenal | E83: Bait and Switch | F83: N/A | G83: Non-rocket burst damage | H83: Universal | I83: S25 pool
A84: Briar's Contempt | B84: Fluted Barrel | C84: Accelerated Coils | D84: Rewind Rounds | E84: Surrounded | F84: N/A | G84: Specialized sustained damage | H84: Universal | I84: Root of Nightmares
A85: Bump in the Night | B85: Quick Launch | C85: Impact Casing | D85: Demolitionist Auto-Loading Holster | E85: Chill Clip Frenzy | F85: N/A | G85: Chill Clip application | H85: SotW | I85: Presage
A86: Calus Mini-Tool | B86: Fluted Barrel | C86: Flared Magwell | D86: Threat Detector | E86: Incandescent | F86: N/A | G86: General primary | H86: Universal | I86: Presage
A87: Cataclysmic | B87: Fluted Barrel | C87: Enhanced Battery | D87: Fourth Time's The Charm | E87: Bait and Switch | F87: N/A | G87: Ranged sustained damage | H87: Universal | I87: Vow of the Disciple
A88: Cataphract GL3 | B88: Quick Launch | C88: Spike Grenades | D88: Envious Assassin Auto-Loading Holster | E88: Bait and Switch Cascade Point | F88: N/A | G88: Non-rocket burst damage | H88: N/A | I88: Trials of Osiris
A89: Cold Comfort | B89: Quick Launch | C89: Impact Casing | D89: Envious Assassin | E89: Bait and Switch | F89: N/A | G89: Burst splash damage | H89: Universal | I89: Ghosts of the Deep
...

Sheet ids_link
A1: Name | B1: Name IDs | C1: Column 1 IDs Counter | D1: Column 1 IDs | E1: Column 2 IDs Counter | F1: Column 2 IDs | G1: Perk 1 IDs Counter | H1: Perk1 IDs | I1: Perk 2 IDs Counter | J1: Perk 2 IDs | K1: Tier | L1: Purpose/Usage/Source
A2: =IF(cleanup_speedrun[[#This Row],[Name]]="","",SUBSTITUTE(cleanup_speedrun[[#This Row],[Name]],CHAR(10)&"BRAVE version","")) -> Ergo Sum | B2: =_xlfn.XLOOKUP(Table3[[#This Row],[Name]],ids_list[NAME],ids_list[IDs]) -> 1681583613 | C2: =LEN(cleanup_speedrun[[#This Row],[Column 1]]) - LEN(SUBSTITUTE(cleanup_speedrun[[#This Row],[Column 1]], CHAR(10), "")) + 1 -> 1 | D2: =IF(_xlfn.XLOOKUP(Table3[[#This Row],[Name]],cleanup_speedrun[Name],cleanup_speedrun[Column 1],"")="Fixed","",IF(cleanup_speedrun[[#This Row],[Column 1]]="","",IF(Table3[[#This Row],[Column 1 IDs Counter]]=2, _xlfn.XLOOKUP(MID(cleanup_speedrun[[#This Row],[Column 1]],1,FIND(CHAR(10),cleanup_speedrun[[#This Row],[Column 1]]&CHAR(10))-1),ids_list[NAME],ids_list[IDs])&","& _xlfn.XLOOKUP(MID(cleanup_speedrun[[#This Row],[Column 1]],FIND(CHAR(10),cleanup_speedrun[[#This Row],[Column 1]]&CHAR(10))+1,FIND(CHAR(10),cleanup_speedrun[[#This Row],[Column 1]]&CHAR(10),FIND(CHAR(10),cleanup_speedrun[[#This Row],[Column 1]]&CHAR(10))+1)-FIND(CHAR(10),cleanup_speedrun[[#This Row],[Column 1]]&CHAR(10))-1),ids_list[NAME],ids_list[IDs]), IF(Table3[[#This Row],[Column 1 IDs Counter]]=3, _xlfn.XLOOKUP(MID(cleanup_speedrun[[#This Row],[Column 1]],1,FIND(CHAR(10),cleanup_speedrun[[#This Row],[Column 1]]&CHAR(10))-1),ids_list[NAME],ids_list[IDs])&","& _xlfn.XLOOKUP(MID(cleanup_speedrun[[#This Row],[Column 1]],FIND(CHAR(10),cleanup_speedrun[[#This Row],[Column 1]]&CHAR(10))+1,FIND(CHAR(10),cleanup_speedrun[[#This Row],[Column 1]]&CHAR(10),FIND(CHAR(10),cleanup_speedrun[[#This Row],[Column 1]]&CHAR(10))+1)-FIND(CHAR(10),cleanup_speedrun[[#This Row],[Column 1]]&CHAR(10))-1),ids_list[NAME],ids_list[IDs])&","& _xlfn.XLOOKUP(MID(cleanup_speedrun[[#This Row],[Column 1]],FIND(CHAR(10),cleanup_speedrun[[#This Row],[Column 1]]&CHAR(10),FIND(CHAR(10),cleanup_speedrun[[#This Row],[Column 1]]&CHAR(10))+1)+1,FIND(CHAR(10),cleanup_speedrun[[#This Row],[Column 1]]&CHAR(10),FIND(CHAR(10),cleanup_speedrun[[#This Row],[Column 1]]&CHAR(10),FIND(CHAR(10),cleanup_speedrun[[#This Row],[Column 1]]&CHAR(10))+1)+1)-FIND(CHAR(10),cleanup_speedrun[[#This Row],[Column 1]]&CHAR(10),FIND(CHAR(10),cleanup_speedrun[[#This Row],[Column 1]]&CHAR(10))+1)-1),ids_list[NAME],ids_list[IDs]), IF(Table3[[#This Row],[Column 1 IDs Counter]]=4, _xlfn.XLOOKUP(MID(cleanup_speedrun[[#This Row],[Column 1]],1,FIND(CHAR(10),cleanup_speedrun[[#This Row],[Column 1]]&CHAR(10))-1),ids_list[NAME],ids_list[IDs])&","& _xlfn.XLOOKUP(MID(cleanup_speedrun[[#This Row],[Column 1]],FIND(CHAR(10),cleanup_speedrun[[#This Row],[Column 1]]&CHAR(10))+1,FIND(CHAR(10),cleanup_speedrun[[#This Row],[Column 1]]&CHAR(10),FIND(CHAR(10),cleanup_speedrun[[#This Row],[Column 1]]&CHAR(10))+1)-FIND(CHAR(10),cleanup_speedrun[[#This Row],[Column 1]]&CHAR(10))-1),ids_list[NAME],ids_list[IDs])&","& _xlfn.XLOOKUP(MID(cleanup_speedrun[[#This Row],[Column 1]],FIND(CHAR(10),cleanup_speedrun[[#This Row],[Column 1]]&CHAR(10),FIND(CHAR(10),cleanup_speedrun[[#This Row],[Column 1]]&CHAR(10))+1)+1,FIND(CHAR(10),cleanup_speedrun[[#This Row],[Column 1]]&CHAR(10),FIND(CHAR(10),cleanup_speedrun[[#This Row],[Column 1]]&CHAR(10),FIND(CHAR(10),cleanup_speedrun[[#This Row],[Column 1]]&CHAR(10))+1)+1)-FIND(CHAR(10),cleanup_speedrun[[#This Row],[Column 1]]&CHAR(10),FIND(CHAR(10),cleanup_speedrun[[#This Row],[Column 1]]&CHAR(10))+1)-1),ids_list[NAME],ids_list[IDs])&","& _xlfn.XLOOKUP(MID(cleanup_speedrun[[#This Row],[Column 1]],FIND(CHAR(10),cleanup_speedrun[[#This Row],[Column 1]]&CHAR(10),FIND(CHAR(10),cleanup_speedrun[[#This Row],[Column 1]]&CHAR(10),FIND(CHAR(10),cleanup_speedrun[[#This Row],[Column 1]]&CHAR(10))+1)+1)+1,LEN(cleanup_speedrun[[#This Row],[Column 1]])),ids_list[NAME],ids_list[IDs]), _xlfn.XLOOKUP(cleanup_speedrun[[#This Row],[Column 1]],ids_list[NAME],ids_list[IDs])))))) -> 1261178282 | E2: =LEN(cleanup_speedrun[[#This Row],[Column 2]]) - LEN(SUBSTITUTE(cleanup_speedrun[[#This Row],[Column 2]], CHAR(10), "")) + 1 -> 1 | F2: =IF(_xlfn.XLOOKUP(Table3[[#This Row],[Name]],cleanup_speedrun[Name],cleanup_speedrun[Column 2],"")="Fixed","",IF(cleanup_speedrun[[#This Row],[Column 2]]="","",IF(Table3[[#This Row],[Column 2 IDs Counter]]=2, _xlfn.XLOOKUP(MID(cleanup_speedrun[[#This Row],[Column 2]],1,FIND(CHAR(10),cleanup_speedrun[[#This Row],[Column 2]]&CHAR(10))-1),ids_list[NAME],ids_list[IDs])&","& _xlfn.XLOOKUP(MID(cleanup_speedrun[[#This Row],[Column 2]],FIND(CHAR(10),cleanup_speedrun[[#This Row],[Column 2]]&CHAR(10))+1,FIND(CHAR(10),cleanup_speedrun[[#This Row],[Column 2]]&CHAR(10),FIND(CHAR(10),cleanup_speedrun[[#This Row],[Column 2]]&CHAR(10))+1)-FIND(CHAR(10),cleanup_speedrun[[#This Row],[Column 2]]&CHAR(10))-1),ids_list[NAME],ids_list[IDs]), IF(Table3[[#This Row],[Column 2 IDs Counter]]=3, _xlfn.XLOOKUP(MID(cleanup_speedrun[[#This Row],[Column 2]],1,FIND(CHAR(10),cleanup_speedrun[[#This Row],[Column 2]]&CHAR(10))-1),ids_list[NAME],ids_list[IDs])&","& _xlfn.XLOOKUP(MID(cleanup_speedrun[[#This Row],[Column 2]],FIND(CHAR(10),cleanup_speedrun[[#This Row],[Column 2]]&CHAR(10))+1,FIND(CHAR(10),cleanup_speedrun[[#This Row],[Column 2]]&CHAR(10),FIND(CHAR(10),cleanup_speedrun[[#This Row],[Column 2]]&CHAR(10))+1)-FIND(CHAR(10),cleanup_speedrun[[#This Row],[Column 2]]&CHAR(10))-1),ids_list[NAME],ids_list[IDs])&","& _xlfn.XLOOKUP(MID(cleanup_speedrun[[#This Row],[Column 2]],FIND(CHAR(10),cleanup_speedrun[[#This Row],[Column 2]]&CHAR(10),FIND(CHAR(10),cleanup_speedrun[[#This Row],[Column 2]]&CHAR(10))+1)+1,FIND(CHAR(10),cleanup_speedrun[[#This Row],[Column 2]]&CHAR(10),FIND(CHAR(10),cleanup_speedrun[[#This Row],[Column 2]]&CHAR(10),FIND(CHAR(10),cleanup_speedrun[[#This Row],[Column 2]]&CHAR(10))+1)+1)-FIND(CHAR(10),cleanup_speedrun[[#This Row],[Column 2]]&CHAR(10),FIND(CHAR(10),cleanup_speedrun[[#This Row],[Column 2]]&CHAR(10))+1)-1),ids_list[NAME],ids_list[IDs]), IF(Table3[[#This Row],[Column 2 IDs Counter]]=4, _xlfn.XLOOKUP(MID(cleanup_speedrun[[#This Row],[Column 2]],1,FIND(CHAR(10),cleanup_speedrun[[#This Row],[Column 2]]&CHAR(10))-1),ids_list[NAME],ids_list[IDs])&","& _xlfn.XLOOKUP(MID(cleanup_speedrun[[#This Row],[Column 2]],FIND(CHAR(10),cleanup_speedrun[[#This Row],[Column 2]]&CHAR(10))+1,FIND(CHAR(10),cleanup_speedrun[[#This Row],[Column 2]]&CHAR(10),FIND(CHAR(10),cleanup_speedrun[[#This Row],[Column 2]]&CHAR(10))+1)-FIND(CHAR(10),cleanup_speedrun[[#This Row],[Column 2]]&CHAR(10))-1),ids_list[NAME],ids_list[IDs])&","& _xlfn.XLOOKUP(MID(cleanup_speedrun[[#This Row],[Column 2]],FIND(CHAR(10),cleanup_speedrun[[#This Row],[Column 2]]&CHAR(10),FIND(CHAR(10),cleanup_speedrun[[#This Row],[Column 2]]&CHAR(10))+1)+1,FIND(CHAR(10),cleanup_speedrun[[#This Row],[Column 2]]&CHAR(10),FIND(CHAR(10),cleanup_speedrun[[#This Row],[Column 2]]&CHAR(10),FIND(CHAR(10),cleanup_speedrun[[#This Row],[Column 2]]&CHAR(10))+1)+1)-FIND(CHAR(10),cleanup_speedrun[[#This Row],[Column 2]]&CHAR(10),FIND(CHAR(10),cleanup_speedrun[[#This Row],[Column 2]]&CHAR(10))+1)-1),ids_list[NAME],ids_list[IDs])&","& _xlfn.XLOOKUP(MID(cleanup_speedrun[[#This Row],[Column 2]],FIND(CHAR(10),cleanup_speedrun[[#This Row],[Column 2]]&CHAR(10),FIND(CHAR(10),cleanup_speedrun[[#This Row],[Column 2]]&CHAR(10),FIND(CHAR(10),cleanup_speedrun[[#This Row],[Column 2]]&CHAR(10))+1)+1)+1,LEN(cleanup_speedrun[[#This Row],[Column 2]])),ids_list[NAME],ids_list[IDs]), _xlfn.XLOOKUP(cleanup_speedrun[[#This Row],[Column 2]],ids_list[NAME],ids_list[IDs])))))) -> 269888150 | G2: =LEN(cleanup_speedrun[[#This Row],[Perk 1]]) - LEN(SUBSTITUTE(cleanup_speedrun[[#This Row],[Perk 1]], CHAR(10), "")) + 1 -> 3 | H2: =IF(_xlfn.XLOOKUP(Table3[[#This Row],[Name]],cleanup_speedrun[Name],cleanup_speedrun[Perk 1],"")="Fixed","",IF(cleanup_speedrun[[#This Row],[Perk 1]]="","",IF(Table3[[#This Row],[Perk 1 IDs Counter]]=2, _xlfn.XLOOKUP(MID(cleanup_speedrun[[#This Row],[Perk 1]],1,FIND(CHAR(10),cleanup_speedrun[[#This Row],[Perk 1]]&CHAR(10))-1),ids_list[NAME],ids_list[IDs])&","& _xlfn.XLOOKUP(MID(cleanup_speedrun[[#This Row],[Perk 1]],FIND(CHAR(10),cleanup_speedrun[[#This Row],[Perk 1]]&CHAR(10))+1,FIND(CHAR(10),cleanup_speedrun[[#This Row],[Perk 1]]&CHAR(10),FIND(CHAR(10),cleanup_speedrun[[#This Row],[Perk 1]]&CHAR(10))+1)-FIND(CHAR(10),cleanup_speedrun[[#This Row],[Perk 1]]&CHAR(10))-1),ids_list[NAME],ids_list[IDs]), IF(Table3[[#This Row],[Perk 1 IDs Counter]]=3, _xlfn.XLOOKUP(MID(cleanup_speedrun[[#This Row],[Perk 1]],1,FIND(CHAR(10),cleanup_speedrun[[#This Row],[Perk 1]]&CHAR(10))-1),ids_list[NAME],ids_list[IDs])&","& _xlfn.XLOOKUP(MID(cleanup_speedrun[[#This Row],[Perk 1]],FIND(CHAR(10),cleanup_speedrun[[#This Row],[Perk 1]]&CHAR(10))+1,FIND(CHAR(10),cleanup_speedrun[[#This Row],[Perk 1]]&CHAR(10),FIND(CHAR(10),cleanup_speedrun[[#This Row],[Perk 1]]&CHAR(10))+1)-FIND(CHAR(10),cleanup_speedrun[[#This Row],[Perk 1]]&CHAR(10))-1),ids_list[NAME],ids_list[IDs])&","& _xlfn.XLOOKUP(MID(cleanup_speedrun[[#This Row],[Perk 1]],FIND(CHAR(10),cleanup_speedrun[[#This Row],[Perk 1]]&CHAR(10),FIND(CHAR(10),cleanup_speedrun[[#This Row],[Perk 1]]&CHAR(10))+1)+1,FIND(CHAR(10),cleanup_speedrun[[#This Row],[Perk 1]]&CHAR(10),FIND(CHAR(10),cleanup_speedrun[[#This Row],[Perk 1]]&CHAR(10),FIND(CHAR(10),cleanup_speedrun[[#This Row],[Perk 1]]&CHAR(10))+1)+1)-FIND(CHAR(10),cleanup_speedrun[[#This Row],[Perk 1]]&CHAR(10),FIND(CHAR(10),cleanup_speedrun[[#This Row],[Perk 1]]&CHAR(10))+1)-1),ids_list[NAME],ids_list[IDs]), IF(Table3[[#This Row],[Perk 1 IDs Counter]]=4, _xlfn.XLOOKUP(MID(cleanup_speedrun[[#This Row],[Perk 1]],1,FIND(CHAR(10),cleanup_speedrun[[#This Row],[Perk 1]]&CHAR(10))-1),ids_list[NAME],ids_list[IDs])&","& _xlfn.XLOOKUP(MID(cleanup_speedrun[[#This Row],[Perk 1]],FIND(CHAR(10),cleanup_speedrun[[#This Row],[Perk 1]]&CHAR(10))+1,FIND(CHAR(10),cleanup_speedrun[[#This Row],[Perk 1]]&CHAR(10),FIND(CHAR(10),cleanup_speedrun[[#This Row],[Perk 1]]&CHAR(10))+1)-FIND(CHAR(10),cleanup_speedrun[[#This Row],[Perk 1]]&CHAR(10))-1),ids_list[NAME],ids_list[IDs])&","& _xlfn.XLOOKUP(MID(cleanup_speedrun[[#This Row],[Perk 1]],FIND(CHAR(10),cleanup_speedrun[[#This Row],[Perk 1]]&CHAR(10),FIND(CHAR(10),cleanup_speedrun[[#This Row],[Perk 1]]&CHAR(10))+1)+1,FIND(CHAR(10),cleanup_speedrun[[#This Row],[Perk 1]]&CHAR(10),FIND(CHAR(10),cleanup_speedrun[[#This Row],[Perk 1]]&CHAR(10),FIND(CHAR(10),cleanup_speedrun[[#This Row],[Perk 1]]&CHAR(10))+1)+1)-FIND(CHAR(10),cleanup_speedrun[[#This Row],[Perk 1]]&CHAR(10),FIND(CHAR(10),cleanup_speedrun[[#This Row],[Perk 1]]&CHAR(10))+1)-1),ids_list[NAME],ids_list[IDs])&","& _xlfn.XLOOKUP(MID(cleanup_speedrun[[#This Row],[Perk 1]],FIND(CHAR(10),cleanup_speedrun[[#This Row],[Perk 1]]&CHAR(10),FIND(CHAR(10),cleanup_speedrun[[#This Row],[Perk 1]]&CHAR(10),FIND(CHAR(10),cleanup_speedrun[[#This Row],[Perk 1]]&CHAR(10))+1)+1)+1,LEN(cleanup_speedrun[[#This Row],[Perk 1]])),ids_list[NAME],ids_list[IDs]), _xlfn.XLOOKUP(cleanup_speedrun[[#This Row],[Perk 1]],ids_list[NAME],ids_list[IDs])))))) -> 183772609, 519046634,2753228730, 474269988, 1458010786, 1713206376, 2108556049,1395789926 | I2: =LEN(cleanup_speedrun[[#This Row],[Perk 2]]) - LEN(SUBSTITUTE(cleanup_speedrun[[#This Row],[Perk 2]], CHAR(10), "")) + 1 -> 3 | J2: =IF(_xlfn.XLOOKUP(Table3[[#This Row],[Name]],cleanup_speedrun[Name],cleanup_speedrun[Perk 2],"")="Fixed","",IF(cleanup_speedrun[[#This Row],[Perk 2]]="","",IF(Table3[[#This Row],[Perk 2 IDs Counter]]=2, _xlfn.XLOOKUP(MID(cleanup_speedrun[[#This Row],[Perk 2]],1,FIND(CHAR(10),cleanup_speedrun[[#This Row],[Perk 2]]&CHAR(10))-1),ids_list[NAME],ids_list[IDs])&","& _xlfn.XLOOKUP(MID(cleanup_speedrun[[#This Row],[Perk 2]],FIND(CHAR(10),cleanup_speedrun[[#This Row],[Perk 2]]&CHAR(10))+1,FIND(CHAR(10),cleanup_speedrun[[#This Row],[Perk 2]]&CHAR(10),FIND(CHAR(10),cleanup_speedrun[[#This Row],[Perk 2]]&CHAR(10))+1)-FIND(CHAR(10),cleanup_speedrun[[#This Row],[Perk 2]]&CHAR(10))-1),ids_list[NAME],ids_list[IDs]), IF(Table3[[#This Row],[Perk 2 IDs Counter]]=3, _xlfn.XLOOKUP(MID(cleanup_speedrun[[#This Row],[Perk 2]],1,FIND(CHAR(10),cleanup_speedrun[[#This Row],[Perk 2]]&CHAR(10))-1),ids_list[NAME],ids_list[IDs])&","& _xlfn.XLOOKUP(MID(cleanup_speedrun[[#This Row],[Perk 2]],FIND(CHAR(10),cleanup_speedrun[[#This Row],[Perk 2]]&CHAR(10))+1,FIND(CHAR(10),cleanup_speedrun[[#This Row],[Perk 2]]&CHAR(10),FIND(CHAR(10),cleanup_speedrun[[#This Row],[Perk 2]]&CHAR(10))+1)-FIND(CHAR(10),cleanup_speedrun[[#This Row],[Perk 2]]&CHAR(10))-1),ids_list[NAME],ids_list[IDs])&","& _xlfn.XLOOKUP(MID(cleanup_speedrun[[#This Row],[Perk 2]],FIND(CHAR(10),cleanup_speedrun[[#This Row],[Perk 2]]&CHAR(10),FIND(CHAR(10),cleanup_speedrun[[#This Row],[Perk 2]]&CHAR(10))+1)+1,FIND(CHAR(10),cleanup_speedrun[[#This Row],[Perk 2]]&CHAR(10),FIND(CHAR(10),cleanup_speedrun[[#This Row],[Perk 2]]&CHAR(10),FIND(CHAR(10),cleanup_speedrun[[#This Row],[Perk 2]]&CHAR(10))+1)+1)-FIND(CHAR(10),cleanup_speedrun[[#This Row],[Perk 2]]&CHAR(10),FIND(CHAR(10),cleanup_speedrun[[#This Row],[Perk 2]]&CHAR(10))+1)-1),ids_list[NAME],ids_list[IDs]), IF(Table3[[#This Row],[Perk 2 IDs Counter]]=4, _xlfn.XLOOKUP(MID(cleanup_speedrun[[#This Row],[Perk 2]],1,FIND(CHAR(10),cleanup_speedrun[[#This Row],[Perk 2]]&CHAR(10))-1),ids_list[NAME],ids_list[IDs])&","& _xlfn.XLOOKUP(MID(cleanup_speedrun[[#This Row],[Perk 2]],FIND(CHAR(10),cleanup_speedrun[[#This Row],[Perk 2]]&CHAR(10))+1,FIND(CHAR(10),cleanup_speedrun[[#This Row],[Perk 2]]&CHAR(10),FIND(CHAR(10),cleanup_speedrun[[#This Row],[Perk 2]]&CHAR(10))+1)-FIND(CHAR(10),cleanup_speedrun[[#This Row],[Perk 2]]&CHAR(10))-1),ids_list[NAME],ids_list[IDs])&","& _xlfn.XLOOKUP(MID(cleanup_speedrun[[#This Row],[Perk 2]],FIND(CHAR(10),cleanup_speedrun[[#This Row],[Perk 2]]&CHAR(10),FIND(CHAR(10),cleanup_speedrun[[#This Row],[Perk 2]]&CHAR(10))+1)+1,FIND(CHAR(10),cleanup_speedrun[[#This Row],[Perk 2]]&CHAR(10),FIND(CHAR(10),cleanup_speedrun[[#This Row],[Perk 2]]&CHAR(10),FIND(CHAR(10),cleanup_speedrun[[#This Row],[Perk 2]]&CHAR(10))+1)+1)-FIND(CHAR(10),cleanup_speedrun[[#This Row],[Perk 2]]&CHAR(10),FIND(CHAR(10),cleanup_speedrun[[#This Row],[Perk 2]]&CHAR(10))+1)-1),ids_list[NAME],ids_list[IDs])&","& _xlfn.XLOOKUP(MID(cleanup_speedrun[[#This Row],[Perk 2]],FIND(CHAR(10),cleanup_speedrun[[#This Row],[Perk 2]]&CHAR(10),FIND(CHAR(10),cleanup_speedrun[[#This Row],[Perk 2]]&CHAR(10),FIND(CHAR(10),cleanup_speedrun[[#This Row],[Perk 2]]&CHAR(10))+1)+1)+1,LEN(cleanup_speedrun[[#This Row],[Perk 2]])),ids_list[NAME],ids_list[IDs]), _xlfn.XLOOKUP(cleanup_speedrun[[#This Row],[Perk 2]],ids_list[NAME],ids_list[IDs])))))) -> 2516532331, 3949068808,1000724343, 1522566605,2962361451, 1959135343 | K2: =IF(cleanup_speedrun[[#This Row],[Tier]]<>"","Tier: "&cleanup_speedrun[[#This Row],[Tier]],"") -> Tier: 1 | L2: =IF(cleanup_speedrun[[#This Row],[Purpose]]<>"","[Purpose]: "&SUBSTITUTE(cleanup_speedrun[[#This Row],[Purpose]],CHAR(10),", "),"")&IF(cleanup_speedrun[[#This Row],[Usage]]<>""," [Usage]: "&cleanup_speedrun[[#This Row],[Usage]],"")&IF(cleanup_speedrun[[#This Row],[Source]]<>""," [Source]: "&cleanup_speedrun[[#This Row],[Source]],"") -> [Purpose]: Splash add clear, Sword boss damage [Usage]: CE, SE [Source]: Pale Heart
A3: =IF(cleanup_speedrun[[#This Row],[Name]]="","",SUBSTITUTE(cleanup_speedrun[[#This Row],[Name]],CHAR(10)&"BRAVE version","")) -> Gizmo Weft | B3: =_xlfn.XLOOKUP(Table3[[#This Row],[Name]],ids_list[NAME],ids_list[IDs]) -> 4069880346, 1572604081 | C3: =LEN(cleanup_speedrun[[#This Row],[Column 1]]) - LEN(SUBSTITUTE(cleanup_speedrun[[#This Row],[Column 1]], CHAR(10), "")) + 1 -> 1 | D3: =IF(_xlfn.XLOOKUP(Table3[[#This Row],[Name]],cleanup_speedrun[Name],cleanup_speedrun[Column 1],"")="Fixed","",IF(cleanup_speedrun[[#This Row],[Column 1]]="","",IF(Table3[[#This Row],[Column 1 IDs Counter]]=2, _xlfn.XLOOKUP(MID(cleanup_speedrun[[#This Row],[Column 1]],1,FIND(CHAR(10),cleanup_speedrun[[#This Row],[Column 1]]&CHAR(10))-1),ids_list[NAME],ids_list[IDs])&","& _xlfn.XLOOKUP(MID(cleanup_speedrun[[#This Row],[Column 1]],FIND(CHAR(10),cleanup_speedrun[[#This Row],[Column 1]]&CHAR(10))+1,FIND(CHAR(10),cleanup_speedrun[[#This Row],[Column 1]]&CHAR(10),FIND(CHAR(10),cleanup_speedrun[[#This Row],[Column 1]]&CHAR(10))+1)-FIND(CHAR(10),cleanup_speedrun[[#This Row],[Column 1]]&CHAR(10))-1),ids_list[NAME],ids_list[IDs]), IF(Table3[[#This Row],[Column 1 IDs Counter]]=3, _xlfn.XLOOKUP(MID(cleanup_speedrun[[#This Row],[Column 1]],1,FIND(CHAR(10),cleanup_speedrun[[#This Row],[Column 1]]&CHAR(10))-1),ids_list[NAME],ids_list[IDs])&","& _xlfn.XLOOKUP(MID(cleanup_speedrun[[#This Row],[Column 1]],FIND(CHAR(10),cleanup_speedrun[[#This Row],[Column 1]]&CHAR(10))+1,FIND(CHAR(10),cleanup_speedrun[[#This Row],[Column 1]]&CHAR(10),FIND(CHAR(10),cleanup_speedrun[[#This Row],[Column 1]]&CHAR(10))+1)-FIND(CHAR(10),cleanup_speedrun[[#This Row],[Column 1]]&CHAR(10))-1),ids_list[NAME],ids_list[IDs])&","& _xlfn.XLOOKUP(MID(cleanup_speedrun[[#This Row],[Column 1]],FIND(CHAR(10),cleanup_speedrun[[#This Row],[Column 1]]&CHAR(10),FIND(CHAR(10),cleanup_speedrun[[#This Row],[Column 1]]&CHAR(10))+1)+1,FIND(CHAR(10),cleanup_speedrun[[#This Row],[Column 1]]&CHAR(10),FIND(CHAR(10),cleanup_speedrun[[#This Row],[Column 1]]&CHAR(10),FIND(CHAR(10),cleanup_speedrun[[#This Row],[Column 1]]&CHAR(10))+1)+1)-FIND(CHAR(10),cleanup_speedrun[[#This Row],[Column 1]]&CHAR(10),FIND(CHAR(10),cleanup_speedrun[[#This Row],[Column 1]]&CHAR(10))+1)-1),ids_list[NAME],ids_list[IDs]), IF(Table3[[#This Row],[Column 1 IDs Counter]]=4, _xlfn.XLOOKUP(MID(cleanup_speedrun[[#This Row],[Column 1]],1,FIND(CHAR(10),cleanup_speedrun[[#This Row],[Column 1]]&CHAR(10))-1),ids_list[NAME],ids_list[IDs])&","& _xlfn.XLOOKUP(MID(cleanup_speedrun[[#This Row],[Column 1]],FIND(CHAR(10),cleanup_speedrun[[#This Row],[Column 1]]&CHAR(10))+1,FIND(CHAR(10),cleanup_speedrun[[#This Row],[Column 1]]&CHAR(10),FIND(CHAR(10),cleanup_speedrun[[#This Row],[Column 1]]&CHAR(10))+1)-FIND(CHAR(10),cleanup_speedrun[[#This Row],[Column 1]]&CHAR(10))-1),ids_list[NAME],ids_list[IDs])&","& _xlfn.XLOOKUP(MID(cleanup_speedrun[[#This Row],[Column 1]],FIND(CHAR(10),cleanup_speedrun[[#This Row],[Column 1]]&CHAR(10),FIND(CHAR(10),cleanup_speedrun[[#This Row],[Column 1]]&CHAR(10))+1)+1,FIND(CHAR(10),cleanup_speedrun[[#This Row],[Column 1]]&CHAR(10),FIND(CHAR(10),cleanup_speedrun[[#This Row],[Column 1]]&CHAR(10),FIND(CHAR(10),cleanup_speedrun[[#This Row],[Column 1]]&CHAR(10))+1)+1)-FIND(CHAR(10),cleanup_speedrun[[#This Row],[Column 1]]&CHAR(10),FIND(CHAR(10),cleanup_speedrun[[#This Row],[Column 1]]&CHAR(10))+1)-1),ids_list[NAME],ids_list[IDs])&","& _xlfn.XLOOKUP(MID(cleanup_speedrun[[#This Row],[Column 1]],FIND(CHAR(10),cleanup_speedrun[[#This Row],[Column 1]]&CHAR(10),FIND(CHAR(10),cleanup_speedrun[[#This Row],[Column 1]]&CHAR(10),FIND(CHAR(10),cleanup_speedrun[[#This Row],[Column 1]]&CHAR(10))+1)+1)+1,LEN(cleanup_speedrun[[#This Row],[Column 1]])),ids_list[NAME],ids_list[IDs]), _xlfn.XLOOKUP(cleanup_speedrun[[#This Row],[Column 1]],ids_list[NAME],ids_list[IDs])))))) -> 3525010810 | E3: =LEN(cleanup_speedrun[[#This Row],[Column 2]]) - LEN(SUBSTITUTE(cleanup_speedrun[[#This Row],[Column 2]], CHAR(10), "")) + 1 -> 3 | F3: =IF(_xlfn.XLOOKUP(Table3[[#This Row],[Name]],cleanup_speedrun[Name],cleanup_speedrun[Column 2],"")="Fixed","",IF(cleanup_speedrun[[#This Row],[Column 2]]="","",IF(Table3[[#This Row],[Column 2 IDs Counter]]=2, _xlfn.XLOOKUP(MID(cleanup_speedrun[[#This Row],[Column 2]],1,FIND(CHAR(10),cleanup_speedrun[[#This Row],[Column 2]]&CHAR(10))-1),ids_list[NAME],ids_list[IDs])&","& _xlfn.XLOOKUP(MID(cleanup_speedrun[[#This Row],[Column 2]],FIND(CHAR(10),cleanup_speedrun[[#This Row],[Column 2]]&CHAR(10))+1,FIND(CHAR(10),cleanup_speedrun[[#This Row],[Column 2]]&CHAR(10),FIND(CHAR(10),cleanup_speedrun[[#This Row],[Column 2]]&CHAR(10))+1)-FIND(CHAR(10),cleanup_speedrun[[#This Row],[Column 2]]&CHAR(10))-1),ids_list[NAME],ids_list[IDs]), IF(Table3[[#This Row],[Column 2 IDs Counter]]=3, _xlfn.XLOOKUP(MID(cleanup_speedrun[[#This Row],[Column 2]],1,FIND(CHAR(10),cleanup_speedrun[[#This Row],[Column 2]]&CHAR(10))-1),ids_list[NAME],ids_list[IDs])&","& _xlfn.XLOOKUP(MID(cleanup_speedrun[[#This Row],[Column 2]],FIND(CHAR(10),cleanup_speedrun[[#This Row],[Column 2]]&CHAR(10))+1,FIND(CHAR(10),cleanup_speedrun[[#This Row],[Column 2]]&CHAR(10),FIND(CHAR(10),cleanup_speedrun[[#This Row],[Column 2]]&CHAR(10))+1)-FIND(CHAR(10),cleanup_speedrun[[#This Row],[Column 2]]&CHAR(10))-1),ids_list[NAME],ids_list[IDs])&","& _xlfn.XLOOKUP(MID(cleanup_speedrun[[#This Row],[Column 2]],FIND(CHAR(10),cleanup_speedrun[[#This Row],[Column 2]]&CHAR(10),FIND(CHAR(10),cleanup_speedrun[[#This Row],[Column 2]]&CHAR(10))+1)+1,FIND(CHAR(10),cleanup_speedrun[[#This Row],[Column 2]]&CHAR(10),FIND(CHAR(10),cleanup_speedrun[[#This Row],[Column 2]]&CHAR(10),FIND(CHAR(10),cleanup_speedrun[[#This Row],[Column 2]]&CHAR(10))+1)+1)-FIND(CHAR(10),cleanup_speedrun[[#This Row],[Column 2]]&CHAR(10),FIND(CHAR(10),cleanup_speedrun[[#This Row],[Column 2]]&CHAR(10))+1)-1),ids_list[NAME],ids_list[IDs]), IF(Table3[[#This Row],[Column 2 IDs Counter]]=4, _xlfn.XLOOKUP(MID(cleanup_speedrun[[#This Row],[Column 2]],1,FIND(CHAR(10),cleanup_speedrun[[#This Row],[Column 2]]&CHAR(10))-1),ids_list[NAME],ids_list[IDs])&","& _xlfn.XLOOKUP(MID(cleanup_speedrun[[#This Row],[Column 2]],FIND(CHAR(10),cleanup_speedrun[[#This Row],[Column 2]]&CHAR(10))+1,FIND(CHAR(10),cleanup_speedrun[[#This Row],[Column 2]]&CHAR(10),FIND(CHAR(10),cleanup_speedrun[[#This Row],[Column 2]]&CHAR(10))+1)-FIND(CHAR(10),cleanup_speedrun[[#This Row],[Column 2]]&CHAR(10))-1),ids_list[NAME],ids_list[IDs])&","& _xlfn.XLOOKUP(MID(cleanup_speedrun[[#This Row],[Column 2]],FIND(CHAR(10),cleanup_speedrun[[#This Row],[Column 2]]&CHAR(10),FIND(CHAR(10),cleanup_speedrun[[#This Row],[Column 2]]&CHAR(10))+1)+1,FIND(CHAR(10),cleanup_speedrun[[#This Row],[Column 2]]&CHAR(10),FIND(CHAR(10),cleanup_speedrun[[#This Row],[Column 2]]&CHAR(10),FIND(CHAR(10),cleanup_speedrun[[#This Row],[Column 2]]&CHAR(10))+1)+1)-FIND(CHAR(10),cleanup_speedrun[[#This Row],[Column 2]]&CHAR(10),FIND(CHAR(10),cleanup_speedrun[[#This Row],[Column 2]]&CHAR(10))+1)-1),ids_list[NAME],ids_list[IDs])&","& _xlfn.XLOOKUP(MID(cleanup_speedrun[[#This Row],[Column 2]],FIND(CHAR(10),cleanup_speedrun[[#This Row],[Column 2]]&CHAR(10),FIND(CHAR(10),cleanup_speedrun[[#This Row],[Column 2]]&CHAR(10),FIND(CHAR(10),cleanup_speedrun[[#This Row],[Column 2]]&CHAR(10))+1)+1)+1,LEN(cleanup_speedrun[[#This Row],[Column 2]])),ids_list[NAME],ids_list[IDs]), _xlfn.XLOOKUP(cleanup_speedrun[[#This Row],[Column 2]],ids_list[NAME],ids_list[IDs])))))) -> 2822142346,3301904089,3373736292 | G3: =LEN(cleanup_speedrun[[#This Row],[Perk 1]]) - LEN(SUBSTITUTE(cleanup_speedrun[[#This Row],[Perk 1]], CHAR(10), "")) + 1 -> 2 | H3: =IF(_xlfn.XLOOKUP(Table3[[#This Row],[Name]],cleanup_speedrun[Name],cleanup_speedrun[Perk 1],"")="Fixed","",IF(cleanup_speedrun[[#This Row],[Perk 1]]="","",IF(Table3[[#This Row],[Perk 1 IDs Counter]]=2, _xlfn.XLOOKUP(MID(cleanup_speedrun[[#This Row],[Perk 1]],1,FIND(CHAR(10),cleanup_speedrun[[#This Row],[Perk 1]]&CHAR(10))-1),ids_list[NAME],ids_list[IDs])&","& _xlfn.XLOOKUP(MID(cleanup_speedrun[[#This Row],[Perk 1]],FIND(CHAR(10),cleanup_speedrun[[#This Row],[Perk 1]]&CHAR(10))+1,FIND(CHAR(10),cleanup_speedrun[[#This Row],[Perk 1]]&CHAR(10),FIND(CHAR(10),cleanup_speedrun[[#This Row],[Perk 1]]&CHAR(10))+1)-FIND(CHAR(10),cleanup_speedrun[[#This Row],[Perk 1]]&CHAR(10))-1),ids_list[NAME],ids_list[IDs]), IF(Table3[[#This Row],[Perk 1 IDs Counter]]=3, _xlfn.XLOOKUP(MID(cleanup_speedrun[[#This Row],[Perk 1]],1,FIND(CHAR(10),cleanup_speedrun[[#This Row],[Perk 1]]&CHAR(10))-1),ids_list[NAME],ids_list[IDs])&","& _xlfn.XLOOKUP(MID(cleanup_speedrun[[#This Row],[Perk 1]],FIND(CHAR(10),cleanup_speedrun[[#This Row],[Perk 1]]&CHAR(10))+1,FIND(CHAR(10),cleanup_speedrun[[#This Row],[Perk 1]]&CHAR(10),FIND(CHAR(10),cleanup_speedrun[[#This Row],[Perk 1]]&CHAR(10))+1)-FIND(CHAR(10),cleanup_speedrun[[#This Row],[Perk 1]]&CHAR(10))-1),ids_list[NAME],ids_list[IDs])&","& _xlfn.XLOOKUP(MID(cleanup_speedrun[[#This Row],[Perk 1]],FIND(CHAR(10),cleanup_speedrun[[#This Row],[Perk 1]]&CHAR(10),FIND(CHAR(10),cleanup_speedrun[[#This Row],[Perk 1]]&CHAR(10))+1)+1,FIND(CHAR(10),cleanup_speedrun[[#This Row],[Perk 1]]&CHAR(10),FIND(CHAR(10),cleanup_speedrun[[#This Row],[Perk 1]]&CHAR(10),FIND(CHAR(10),cleanup_speedrun[[#This Row],[Perk 1]]&CHAR(10))+1)+1)-FIND(CHAR(10),cleanup_speedrun[[#This Row],[Perk 1]]&CHAR(10),FIND(CHAR(10),cleanup_speedrun[[#This Row],[Perk 1]]&CHAR(10))+1)-1),ids_list[NAME],ids_list[IDs]), IF(Table3[[#This Row],[Perk 1 IDs Counter]]=4, _xlfn.XLOOKUP(MID(cleanup_speedrun[[#This Row],[Perk 1]],1,FIND(CHAR(10),cleanup_speedrun[[#This Row],[Perk 1]]&CHAR(10))-1),ids_list[NAME],ids_list[IDs])&","& _xlfn.XLOOKUP(MID(cleanup_speedrun[[#This Row],[Perk 1]],FIND(CHAR(10),cleanup_speedrun[[#This Row],[Perk 1]]&CHAR(10))+1,FIND(CHAR(10),cleanup_speedrun[[#This Row],[Perk 1]]&CHAR(10),FIND(CHAR(10),cleanup_speedrun[[#This Row],[Perk 1]]&CHAR(10))+1)-FIND(CHAR(10),cleanup_speedrun[[#This Row],[Perk 1]]&CHAR(10))-1),ids_list[NAME],ids_list[IDs])&","& _xlfn.XLOOKUP(MID(cleanup_speedrun[[#This Row],[Perk 1]],FIND(CHAR(10),cleanup_speedrun[[#This Row],[Perk 1]]&CHAR(10),FIND(CHAR(10),cleanup_speedrun[[#This Row],[Perk 1]]&CHAR(10))+1)+1,FIND(CHAR(10),cleanup_speedrun[[#This Row],[Perk 1]]&CHAR(10),FIND(CHAR(10),cleanup_speedrun[[#This Row],[Perk 1]]&CHAR(10),FIND(CHAR(10),cleanup_speedrun[[#This Row],[Perk 1]]&CHAR(10))+1)+1)-FIND(CHAR(10),cleanup_speedrun[[#This Row],[Perk 1]]&CHAR(10),FIND(CHAR(10),cleanup_speedrun[[#This Row],[Perk 1]]&CHAR(10))+1)-1),ids_list[NAME],ids_list[IDs])&","& _xlfn.XLOOKUP(MID(cleanup_speedrun[[#This Row],[Perk 1]],FIND(CHAR(10),cleanup_speedrun[[#This Row],[Perk 1]]&CHAR(10),FIND(CHAR(10),cleanup_speedrun[[#This Row],[Perk 1]]&CHAR(10),FIND(CHAR(10),cleanup_speedrun[[#This Row],[Perk 1]]&CHAR(10))+1)+1)+1,LEN(cleanup_speedrun[[#This Row],[Perk 1]])),ids_list[NAME],ids_list[IDs]), _xlfn.XLOOKUP(cleanup_speedrun[[#This Row],[Perk 1]],ids_list[NAME],ids_list[IDs])))))) -> 1421772400,3161816588 | I3: =LEN(cleanup_speedrun[[#This Row],[Perk 2]]) - LEN(SUBSTITUTE(cleanup_speedrun[[#This Row],[Perk 2]], CHAR(10), "")) + 1 -> 1 | J3: =IF(_xlfn.XLOOKUP(Table3[[#This Row],[Name]],cleanup_speedrun[Name],cleanup_speedrun[Perk 2],"")="Fixed","",IF(cleanup_speedrun[[#This Row],[Perk 2]]="","",IF(Table3[[#This Row],[Perk 2 IDs Counter]]=2, _xlfn.XLOOKUP(MID(cleanup_speedrun[[#This Row],[Perk 2]],1,FIND(CHAR(10),cleanup_speedrun[[#This Row],[Perk 2]]&CHAR(10))-1),ids_list[NAME],ids_list[IDs])&","& _xlfn.XLOOKUP(MID(cleanup_speedrun[[#This Row],[Perk 2]],FIND(CHAR(10),cleanup_speedrun[[#This Row],[Perk 2]]&CHAR(10))+1,FIND(CHAR(10),cleanup_speedrun[[#This Row],[Perk 2]]&CHAR(10),FIND(CHAR(10),cleanup_speedrun[[#This Row],[Perk 2]]&CHAR(10))+1)-FIND(CHAR(10),cleanup_speedrun[[#This Row],[Perk 2]]&CHAR(10))-1),ids_list[NAME],ids_list[IDs]), IF(Table3[[#This Row],[Perk 2 IDs Counter]]=3, _xlfn.XLOOKUP(MID(cleanup_speedrun[[#This Row],[Perk 2]],1,FIND(CHAR(10),cleanup_speedrun[[#This Row],[Perk 2]]&CHAR(10))-1),ids_list[NAME],ids_list[IDs])&","& _xlfn.XLOOKUP(MID(cleanup_speedrun[[#This Row],[Perk 2]],FIND(CHAR(10),cleanup_speedrun[[#This Row],[Perk 2]]&CHAR(10))+1,FIND(CHAR(10),cleanup_speedrun[[#This Row],[Perk 2]]&CHAR(10),FIND(CHAR(10),cleanup_speedrun[[#This Row],[Perk 2]]&CHAR(10))+1)-FIND(CHAR(10),cleanup_speedrun[[#This Row],[Perk 2]]&CHAR(10))-1),ids_list[NAME],ids_list[IDs])&","& _xlfn.XLOOKUP(MID(cleanup_speedrun[[#This Row],[Perk 2]],FIND(CHAR(10),cleanup_speedrun[[#This Row],[Perk 2]]&CHAR(10),FIND(CHAR(10),cleanup_speedrun[[#This Row],[Perk 2]]&CHAR(10))+1)+1,FIND(CHAR(10),cleanup_speedrun[[#This Row],[Perk 2]]&CHAR(10),FIND(CHAR(10),cleanup_speedrun[[#This Row],[Perk 2]]&CHAR(10),FIND(CHAR(10),cleanup_speedrun[[#This Row],[Perk 2]]&CHAR(10))+1)+1)-FIND(CHAR(10),cleanup_speedrun[[#This Row],[Perk 2]]&CHAR(10),FIND(CHAR(10),cleanup_speedrun[[#This Row],[Perk 2]]&CHAR(10))+1)-1),ids_list[NAME],ids_list[IDs]), IF(Table3[[#This Row],[Perk 2 IDs Counter]]=4, _xlfn.XLOOKUP(MID(cleanup_speedrun[[#This Row],[Perk 2]],1,FIND(CHAR(10),cleanup_speedrun[[#This Row],[Perk 2]]&CHAR(10))-1),ids_list[NAME],ids_list[IDs])&","& _xlfn.XLOOKUP(MID(cleanup_speedrun[[#This Row],[Perk 2]],FIND(CHAR(10),cleanup_speedrun[[#This Row],[Perk 2]]&CHAR(10))+1,FIND(CHAR(10),cleanup_speedrun[[#This Row],[Perk 2]]&CHAR(10),FIND(CHAR(10),cleanup_speedrun[[#This Row],[Perk 2]]&CHAR(10))+1)-FIND(CHAR(10),cleanup_speedrun[[#This Row],[Perk 2]]&CHAR(10))-1),ids_list[NAME],ids_list[IDs])&","& _xlfn.XLOOKUP(MID(cleanup_speedrun[[#This Row],[Perk 2]],FIND(CHAR(10),cleanup_speedrun[[#This Row],[Perk 2]]&CHAR(10),FIND(CHAR(10),cleanup_speedrun[[#This Row],[Perk 2]]&CHAR(10))+1)+1,FIND(CHAR(10),cleanup_speedrun[[#This Row],[Perk 2]]&CHAR(10),FIND(CHAR(10),cleanup_speedrun[[#This Row],[Perk 2]]&CHAR(10),FIND(CHAR(10),cleanup_speedrun[[#This Row],[Perk 2]]&CHAR(10))+1)+1)-FIND(CHAR(10),cleanup_speedrun[[#This Row],[Perk 2]]&CHAR(10),FIND(CHAR(10),cleanup_speedrun[[#This Row],[Perk 2]]&CHAR(10))+1)-1),ids_list[NAME],ids_list[IDs])&","& _xlfn.XLOOKUP(MID(cleanup_speedrun[[#This Row],[Perk 2]],FIND(CHAR(10),cleanup_speedrun[[#This Row],[Perk 2]]&CHAR(10),FIND(CHAR(10),cleanup_speedrun[[#This Row],[Perk 2]]&CHAR(10),FIND(CHAR(10),cleanup_speedrun[[#This Row],[Perk 2]]&CHAR(10))+1)+1)+1,LEN(cleanup_speedrun[[#This Row],[Perk 2]])),ids_list[NAME],ids_list[IDs]), _xlfn.XLOOKUP(cleanup_speedrun[[#This Row],[Perk 2]],ids_list[NAME],ids_list[IDs])))))) -> 1439600632 | K3: =IF(cleanup_speedrun[[#This Row],[Tier]]<>"","Tier: "&cleanup_speedrun[[#This Row],[Tier]],"") -> Tier: 1 | L3: =IF(cleanup_speedrun[[#This Row],[Purpose]]<>"","[Purpose]: "&SUBSTITUTE(cleanup_speedrun[[#This Row],[Purpose]],CHAR(10),", "),"")&IF(cleanup_speedrun[[#This Row],[Usage]]<>""," [Usage]: "&cleanup_speedrun[[#This Row],[Usage]],"")&IF(cleanup_speedrun[[#This Row],[Source]]<>""," [Source]: "&cleanup_speedrun[[#This Row],[Source]],"") -> [Purpose]: Boosting jump height [Usage]: Universal [Source]: Event drop
